<?xml version="1.0"?>
<robot name="simple_humanoid">

  <link name="base_link">
    <visual>
      <geometry>
        <box size="0.1 0.1 0.05" />
      </geometry>
      <material name="blue">
        <color rgba="0 0 0.8 1"/>
      </material>
    </visual>
    <collision>
      <geometry>
        <box size="0.1 0.1 0.05" />
      </geometry>
    </collision>
    <inertial>
      <mass value="0.1" />
      <inertia ixx="0.001" ixy="0" ixz="0" iyy="0.001" iyz="0" izz="0.001" />
    </inertial>
  </link>

  <link name="torso_link">
    <visual>
      <geometry>
        <box size="0.1 0.05 0.2" />
      </geometry>
      <material name="green">
        <color rgba="0 0.8 0 1"/>
      </material>
    </visual>
    <collision>
      <geometry>
        <box size="0.1 0.05 0.2" />
      </geometry>
    </collision>
    <inertial>
      <mass value="0.5" />
      <inertia ixx="0.01" ixy="0" ixz="0" iyy="0.01" iyz="0" izz="0.01" />
    </inertial>
  </link>

  <joint name="base_to_torso_joint" type="fixed">
    <parent link="base_link"/>
    <child link="torso_link"/>
    <origin xyz="0 0 0.125" rpy="0 0 0"/>
  </joint>

  <link name="head_link">
    <visual>
      <geometry>
        <sphere radius="0.05" />
      </geometry>
      <material name="red">
        <color rgba="0.8 0 0 1"/>
      </material>
    </visual>
    <collision>
      <geometry>
        <sphere radius="0.05" />
      </geometry>
    </collision>
    <inertial>
      <mass value="0.1" />
      <inertia ixx="0.0005" ixy="0" ixz="0" iyy="0.0005" iyz="0" izz="0.0005" />
    </inertial>
  </link>

  <joint name="torso_to_head_joint" type="revolute">
    <parent link="torso_link"/>
    <child link="head_link"/>
    <origin xyz="0 0 0.125" rpy="0 0 0"/>
    <axis xyz="0 0 1"/>
    <limit lower="-1.57" upper="1.57" effort="10" velocity="1"/>
  </joint>

</robot>
